Workbook

Sheet tipp
A1: https://sports.sportingbet.com/en/sports?wm=4582295&affiliate=ia_com&btag=a_26261b_44427c_14320d_&siteid=26261#leagueIds=5419&sportId=12 | C1: 1 | D1: X | E1: 2 | F1: final | G1: team1 | H1: team2 | I1: letter | J1: szorzó | K1: Csiszi | L1: Viki | M1: Kinga | N1: Tomi | O1: Benő | Q1: Geri | R1: Andris
A2: Ki lesz a bajnok? | K2: Sweden | L2: Finland | M2: Finland | N2: Sweden | O2: United States | Q2: Russia
A3: Ki lesz az ezüstérmes? | K3: Russia | L3: Germany | M3: Sweden | N3: Russia | O3: Canada | Q3: Finland
A4: Ki lesz a bronzérmes? | K4: Canada | L4: Czech Republic | M4: Russia | N4: Canada | O4: Sweden | Q4: Canada
A5: Russia | B5: France | C5: 1.08 | D5: 43409 | E5: 17 | F5: 7:0 | G5: =left(F5,find(":",F5)-1) -> 7 | H5: =right(F5,(len(F5)-find(":",F5))) -> 0 | I5: =if(G5>H5,1,if(H5>G5,2,"x")) -> 1 | J5: =iferror(HLOOKUP(I5,$C$1:$E$100,row(),true),"") -> 1.08 | K5: 4:0 | L5: 5:1 | M5: 3:1 | N5: 3:2 | O5: 4:1 | Q5: 5:1 | R5: 5:2
A6: Sweden | B6: Belarus | C6: 1.17 | D6: 8.5 | E6: 10.5 | F6: 5:0 | G6: =left(F6,find(":",F6)-1) -> 5 | H6: =right(F6,(len(F6)-find(":",F6))) -> 0 | I6: =if(G6>H6,1,if(H6>G6,2,"x")) -> 1 | J6: =iferror(HLOOKUP(I6,$C$1:$E$100,row(),true),"") -> 1.17 | K6: 6:0 | L6: 3:0 | M6: 4:0 | N6: 4:1 | O6: 5:0 | Q6: 2:3 | R6: 3:0
A7: United States | B7: Canada | C7: 4.5 | D7: 5 | E7: 1.55 | F7: 4:4 | G7: =left(F7,find(":",F7)-1) -> 4 | H7: =right(F7,(len(F7)-find(":",F7))) -> 4 | I7: =if(G7>H7,1,if(H7>G7,2,"x")) -> x | J7: =iferror(HLOOKUP(I7,$C$1:$E$100,row(),true),"") -> 5 | K7: 1:3 | L7: 2:4 | M7: 2:3 | N7: 2:1 | O7: 3:3 | Q7: 3:3 | R7: 1:3
A8: Germany | B8: Denmark | C8: 2.3 | D8: 4 | E8: 2.7 | F8: 2:2 | G8: =left(F8,find(":",F8)-1) -> 2 | H8: =right(F8,(len(F8)-find(":",F8))) -> 2 | I8: =if(G8>H8,1,if(H8>G8,2,"x")) -> x | J8: =iferror(HLOOKUP(I8,$C$1:$E$100,row(),true),"") -> 4 | K8: 2:4 | L8: 3:2 | M8: 1:2 | N8: 2:2 | O8: 2:3 | Q8: 2:1 | R8: 2:1
A9: Switzerland | B9: Austria | C9: 1.36 | D9: 6 | E9: 6 | F9: 2:2 | G9: =left(F9,find(":",F9)-1) -> 2 | H9: =right(F9,(len(F9)-find(":",F9))) -> 2 | I9: =if(G9>H9,1,if(H9>G9,2,"x")) -> x | J9: =iferror(HLOOKUP(I9,$C$1:$E$100,row(),true),"") -> 6 | K9: 5:0 | L9: 3:1 | M9: 2:2 | N9: 5:1 | O9: 5:2 | Q9: 3:0 | R9: 3:0
A10: France | B10: Belarus | C10: 2.9 | D10: 4.2 | E10: 2.05 | F10: 6:2 | G10: =left(F10,find(":",F10)-1) -> 6 | H10: =right(F10,(len(F10)-find(":",F10))) -> 2 | I10: =if(G10>H10,1,if(H10>G10,2,"x")) -> 1 | J10: =iferror(HLOOKUP(I10,$C$1:$E$100,row(),true),"") -> 2.9 | K10: 1:1 | L10: 2:4 | M10: 3:1 | N10: 3:4 | O10: 0:2 | Q10: 1:0 | R10: 1:3
A11: Czech Republic | B11: Slovakia | C11: 1.42 | D11: 5.25 | E11: 5.75 | F11: 2:2 | G11: =left(F11,find(":",F11)-1) -> 2 | H11: =right(F11,(len(F11)-find(":",F11))) -> 2 | I11: =if(G11>H11,1,if(H11>G11,2,"x")) -> x | J11: =iferror(HLOOKUP(I11,$C$1:$E$100,row(),true),"") -> 5.25 | K11: 4:2 | L11: 4:1 | M11: 4:1 | N11: 4:2 | O11: 4:1 | Q11: 4:3 | R11: 2:2
A12: Norway | B12: Latvia | C12: 2.25 | D12: 4 | E12: 2.65 | F12: 2:2 | G12: =left(F12,find(":",F12)-1) -> 2 | H12: =right(F12,(len(F12)-find(":",F12))) -> 2 | I12: =if(G12>H12,1,if(H12>G12,2,"x")) -> x | J12: =iferror(HLOOKUP(I12,$C$1:$E$100,row(),true),"") -> 4 | K12: 2:4 | L12: 2:3 | M12: 1:2 | N12: 1:1 | O12: 3:5 | Q12: 4:4 | R12: 2:2
A13: Finland | B13: South Korea | C13: 1.02 | D13: 17 | E13: 36 | F13: 8:1 | G13: =left(F13,find(":",F13)-1) -> 8 | H13: =right(F13,(len(F13)-find(":",F13))) -> 1 | I13: =if(G13>H13,1,if(H13>G13,2,"x")) -> 1 | J13: =iferror(HLOOKUP(I13,$C$1:$E$100,row(),true),"") -> 1.02 | K13: 6:0 | L13: 5:1 | M13: 5:0 | N13: 7:1 | O13: 3:0 | Q13: 7:0 | R13: 6:0
A14: Denmark | B14: United States | C14: 7 | D14: 6.75 | E14: 1.28 | F14: 0:4 | G14: =left(F14,find(":",F14)-1) -> 0 | H14: =right(F14,(len(F14)-find(":",F14))) -> 4 | I14: =if(G14>H14,1,if(H14>G14,2,"x")) -> 2 | J14: =iferror(HLOOKUP(I14,$C$1:$E$100,row(),true),"") -> 1.28 | K14: 1:4 | L14: 2:4 | M14: 2:4 | N14: 0:3 | O14: 2:4 | Q14: 2:5 | R14: 1:4
A15: Austria | B15: Russia | C15: 18 | D15: 14 | E15: 1.05 | F15: 0:7 | G15: =left(F15,find(":",F15)-1) -> 0 | H15: =right(F15,(len(F15)-find(":",F15))) -> 7 | I15: =if(G15>H15,1,if(H15>G15,2,"x")) -> 2 | J15: =iferror(HLOOKUP(I15,$C$1:$E$100,row(),true),"") -> 1.05 | K15: 0:6 | L15: 1:6 | M15: 0:5 | N15: 1:5 | O15: 0:6 | Q15: 0:4 | R15: 1:7
A16: Sweden | B16: Czech Republic | C16: 2.15 | D16: 4.25 | E16: 2.7 | F16: 3:2 | G16: =left(F16,find(":",F16)-1) -> 3 | H16: =right(F16,(len(F16)-find(":",F16))) -> 2 | I16: =if(G16>H16,1,if(H16>G16,2,"x")) -> 1 | J16: =iferror(HLOOKUP(I16,$C$1:$E$100,row(),true),"") -> 2.15 | K16: 4:1 | L16: 2:3 | M16: 4:1 | O16: 3:1
A17: Slovakia | B17: Switzerland | C17: 2.75 | D17: 4.25 | E17: 2.1 | F17: 0:2 | G17: =left(F17,find(":",F17)-1) -> 0 | H17: =right(F17,(len(F17)-find(":",F17))) -> 2 | I17: =if(G17>H17,1,if(H17>G17,2,"x")) -> 2 | J17: =iferror(HLOOKUP(I17,$C$1:$E$100,row(),true),"") -> 2.1 | K17: 2:2 | L17: 2:4 | M17: 3:1 | O17: 1:3 | Q17: 3:2
A18: South Korea | B18: Canada | C18: 35 | D18: 25 | E18: 1.01 | F18: 0:10 | G18: =left(F18,find(":",F18)-1) -> 0 | H18: =right(F18,(len(F18)-find(":",F18))) -> 10 | I18: =if(G18>H18,1,if(H18>G18,2,"x")) -> 2 | J18: =iferror(HLOOKUP(I18,$C$1:$E$100,row(),true),"") -> 1.01 | K18: 0:7 | L18: 1:7 | M18: 0:8 | O18: 1:9
A19: Germany | B19: Norway | C19: 1.9 | D19: 4.4 | E19: 3.1 | F19: 4:4 | G19: =left(F19,find(":",F19)-1) -> 4 | H19: =right(F19,(len(F19)-find(":",F19))) -> 4 | I19: =if(G19>H19,1,if(H19>G19,2,"x")) -> x | J19: =iferror(HLOOKUP(I19,$C$1:$E$100,row(),true),"") -> 4.4 | K19: 2:2 | L19: 4:2 | M19: 2:3 | O19: 3:2
A20: Latvia | B20: Finland | C20: 8.5 | D20: 7 | E20: 1.22 | F20: 1:8 | G20: =left(F20,find(":",F20)-1) -> 1 | H20: =right(F20,(len(F20)-find(":",F20))) -> 8 | I20: =if(G20>H20,1,if(H20>G20,2,"x")) -> 2 | J20: =iferror(HLOOKUP(I20,$C$1:$E$100,row(),true),"") -> 1.22 | K20: 2:4 | L20: 1:4 | M20: 2:5 | O20: 1:3 | Q20: 1:6
A21: Belarus | B21: Russia | C21: 10 | D21: 9 | E21: 1.15 | F21: 0:6 | G21: =left(F21,find(":",F21)-1) -> 0 | H21: =right(F21,(len(F21)-find(":",F21))) -> 6 | I21: =if(G21>H21,1,if(H21>G21,2,"x")) -> 2 | J21: =iferror(HLOOKUP(I21,$C$1:$E$100,row(),true),"") -> 1.15 | K21: 0:5 | L21: 0:8 | M21: 1:6 | N21: 1:7 | O21: 2:6 | Q21: 2:5
A22: Sweden | B22: France | C22: 1.09 | D22: 10.5 | E22: 18 | F22: 4:0 | G22: =left(F22,find(":",F22)-1) -> 4 | H22: =right(F22,(len(F22)-find(":",F22))) -> 0 | I22: =if(G22>H22,1,if(H22>G22,2,"x")) -> 1 | J22: =iferror(HLOOKUP(I22,$C$1:$E$100,row(),true),"") -> 1.09 | K22: 2:2 | L22: 4:2 | M22: 5:2 | N22: 5:0 | O22: 4:0 | Q22: 6:1
A23: United States | B23: Germany | C23: 1.5 | D23: 5 | E23: 4.6 | F23: 3:0 | G23: =left(F23,find(":",F23)-1) -> 3 | H23: =right(F23,(len(F23)-find(":",F23))) -> 0 | I23: =if(G23>H23,1,if(H23>G23,2,"x")) -> 1 | J23: =iferror(HLOOKUP(I23,$C$1:$E$100,row(),true),"") -> 1.5 | K23: 4:1 | L23: 3:2 | M23: 5:2 | N23: 4:1 | O23: 4:2 | Q23: 4:1
A24: Canada | B24: Denmark | C24: 1.11 | D24: 9.5 | E24: 14 | F24: 7:1 | G24: =left(F24,find(":",F24)-1) -> 7 | H24: =right(F24,(len(F24)-find(":",F24))) -> 1 | I24: =if(G24>H24,1,if(H24>G24,2,"x")) -> 1 | J24: =iferror(HLOOKUP(I24,$C$1:$E$100,row(),true),"") -> 1.11 | K24: 5:1 | L24: 7:1 | M24: 5:2 | N24: 6:0 | O24: 5:1 | Q24: 6:0
A25: Austria | B25: Slovakia | C25: 5.75 | D25: 5.75 | E25: 1.36 | F25: 2:4 | G25: =left(F25,find(":",F25)-1) -> 2 | H25: =right(F25,(len(F25)-find(":",F25))) -> 4 | I25: =if(G25>H25,1,if(H25>G25,2,"x")) -> 2 | J25: =iferror(HLOOKUP(I25,$C$1:$E$100,row(),true),"") -> 1.36 | K25: 2:2 | L25: 4:3 | M25: 1:3 | N25: 2:1 | O25: 1:2 | Q25: 2:5
A26: Czech Republic | B26: Switzerland | C26: 1.72 | D26: 4.5 | E26: 3.6 | F26: 4:4 | G26: =left(F26,find(":",F26)-1) -> 4 | H26: =right(F26,(len(F26)-find(":",F26))) -> 4 | I26: =if(G26>H26,1,if(H26>G26,2,"x")) -> x | J26: =iferror(HLOOKUP(I26,$C$1:$E$100,row(),true),"") -> 4.5 | K26: 4:2 | L26: 2:2 | M26: 2:3 | N26: 3:2 | O26: 2:2 | Q26: 3:1
A27: South Korea | B27: Latvia | C27: 5.2 | D27: 5.7 | E27: 1.4 | F27: 0:5 | G27: =left(F27,find(":",F27)-1) -> 0 | H27: =right(F27,(len(F27)-find(":",F27))) -> 5 | I27: =if(G27>H27,1,if(H27>G27,2,"x")) -> 2 | J27: =iferror(HLOOKUP(I27,$C$1:$E$100,row(),true),"") -> 1.4 | K27: 1:5 | L27: 1:4 | M27: 0:3 | N27: 1:4 | O27: 1:3 | Q27: 1:2
A28: Finland | B28: Norway | C28: 1.33 | D28: 6 | E28: 6.25 | F28: 7:0 | G28: =left(F28,find(":",F28)-1) -> 7 | H28: =right(F28,(len(F28)-find(":",F28))) -> 0 | I28: =if(G28>H28,1,if(H28>G28,2,"x")) -> 1 | J28: =iferror(HLOOKUP(I28,$C$1:$E$100,row(),true),"") -> 1.33 | K28: 6:0 | L28: 6:1 | M28: 3:0 | N28: 5:2 | O28: 5:1 | Q28: 5:0
A29: Switzerland | B29: Belarus | C29: 1.7 | D29: 4.5 | E29: 3.7 | F29: 5:2 | G29: =left(F29,find(":",F29)-1) -> 5 | H29: =right(F29,(len(F29)-find(":",F29))) -> 2 | I29: =if(G29>H29,1,if(H29>G29,2,"x")) -> 1 | J29: =iferror(HLOOKUP(I29,$C$1:$E$100,row(),true),"") -> 1.7 | K29: 4:1 | L29: 6:1 | M29: 3:2 | N29: 4:1 | O29: 3:3 | Q29: 2:2
A30: Sweden | B30: Austria | C30: 1.05 | D30: 14 | E30: 18 | F30: 7:0 | G30: =left(F30,find(":",F30)-1) -> 7 | H30: =right(F30,(len(F30)-find(":",F30))) -> 0 | I30: =if(G30>H30,1,if(H30>G30,2,"x")) -> 1 | J30: =iferror(HLOOKUP(I30,$C$1:$E$100,row(),true),"") -> 1.05 | K30: 6:0 | L30: 7:1 | M30: 4:1 | N30: 5:0 | O30: 5:0 | Q30: 4:0
A31: Germany | B31: South Korea | C31: 1.22 | D31: 7 | E31: 8.5 | F31: 6:1 | G31: =left(F31,find(":",F31)-1) -> 6 | H31: =right(F31,(len(F31)-find(":",F31))) -> 1 | I31: =if(G31>H31,1,if(H31>G31,2,"x")) -> 1 | J31: =iferror(HLOOKUP(I31,$C$1:$E$100,row(),true),"") -> 1.22 | K31: 6:0 | L31: 6:0 | M31: 2:0 | N31: 3:0 | O31: 5:1 | Q31: 3:0
A32: Finland | B32: Denmark | C32: 1.33 | D32: 6 | E32: 6 | F32: 2:3 | G32: =left(F32,find(":",F32)-1) -> 2 | H32: =right(F32,(len(F32)-find(":",F32))) -> 3 | I32: =if(G32>H32,1,if(H32>G32,2,"x")) -> 2 | J32: =iferror(HLOOKUP(I32,$C$1:$E$100,row(),true),"") -> 6 | K32: 4:0 | L32: 8:1 | M32: 4:2 | N32: 3:0 | O32: 4:2 | Q32: 4:2
... A45: Denmark | B45: South Korea | C45: 1.2 | D45: 8 | E45: 8.5 | F45: 3:1 | G45: =left(F45,find(":",F45)-1) -> 3 | H45: =right(F45,(len(F45)-find(":",F45))) -> 1 | I45: =if(G45>H45,1,if(H45>G45,2,"x")) -> 1 | J45: =iferror(HLOOKUP(I45,$C$1:$E$100,row(),true),"") -> 1.2 | K45: 4:1 | L45: 5:0 | M45: 4:2 | N45: 4:1 | O45: 6:1 | Q45: 2:1
A46: Canada | B46: Finland | C46: 1.65 | D46: 4.6 | E46: 3.85 | F46: 1:5 | G46: =left(F46,find(":",F46)-1) -> 1 | H46: =right(F46,(len(F46)-find(":",F46))) -> 5 | I46: =if(G46>H46,1,if(H46>G46,2,"x")) -> 2 | J46: =iferror(HLOOKUP(I46,$C$1:$E$100,row(),true),"") -> 3.85 | K46: 3:3 | L46: 2:3 | M46: 3:4 | O46: 4:4 | Q46: 4:4
A47: France | B47: Czech Republic | C47: 7 | D47: 7.2 | E47: 1.25 | F47: 0:6 | G47: =left(F47,find(":",F47)-1) -> 0 | H47: =right(F47,(len(F47)-find(":",F47))) -> 6 | I47: =if(G47>H47,1,if(H47>G47,2,"x")) -> 2 | J47: =iferror(HLOOKUP(I47,$C$1:$E$100,row(),true),"") -> 1.25 | K47: 3:3 | L47: 1:5 | M47: 1:3 | N47: 2:5 | O47: 2:5 | Q47: 2:4
A48: Switzerland | B48: Sweden | C48: 6 | D48: 6.25 | E48: 1.33 | F48: 3:5 | G48: =left(F48,find(":",F48)-1) -> 3 | H48: =right(F48,(len(F48)-find(":",F48))) -> 5 | I48: =if(G48>H48,1,if(H48>G48,2,"x")) -> 2 | J48: =iferror(HLOOKUP(I48,$C$1:$E$100,row(),true),"") -> 1.33 | K48: 3:3 | L48: 3:2 | M48: 1:3 | N48: 2:4 | O48: 1:3 | Q48: 2:4
A49: Norway | B49: United States | C49: 7 | D49: 6.5 | E49: 1.28 | F49: 3:9 | G49: =left(F49,find(":",F49)-1) -> 3 | H49: =right(F49,(len(F49)-find(":",F49))) -> 9 | I49: =if(G49>H49,1,if(H49>G49,2,"x")) -> 2 | J49: =iferror(HLOOKUP(I49,$C$1:$E$100,row(),true),"") -> 1.28 | K49: 3:3 | L49: 2:6 | M49: 0:4 | N49: 1:7 | O49: 1:5 | Q49: 1:6
A50: Germany | B50: Finland | C50: 5 | D50: 5.25 | E50: 1.45 | F50: 2:2 | G50: =left(F50,find(":",F50)-1) -> 2 | H50: =right(F50,(len(F50)-find(":",F50))) -> 2 | I50: =if(G50>H50,1,if(H50>G50,2,"x")) -> x | J50: =iferror(HLOOKUP(I50,$C$1:$E$100,row(),true),"") -> 5.25 | K50: 3:3 | L50: 1:5 | M50: 2:4 | N50: 0:4 | O50: 2:2 | Q50: 1:4
A51: Russia | B51: Slovakia | C51: 1.25 | D51: 7.2 | E51: 7 | F51: 4:0 | G51: =left(F51,find(":",F51)-1) -> 4 | H51: =right(F51,(len(F51)-find(":",F51))) -> 0 | I51: =if(G51>H51,1,if(H51>G51,2,"x")) -> 1 | J51: =iferror(HLOOKUP(I51,$C$1:$E$100,row(),true),"") -> 1.25 | K51: 3:3 | L51: 3:3 | M51: 5:2 | N51: 3:3 | O51: 5:1 | Q51: 2:2
A52: Czech Republic | B52: Austria | C52: 1.13 | D52: 10 | E52: 11 | F52: 4:3 | G52: =left(F52,find(":",F52)-1) -> 4 | H52: =right(F52,(len(F52)-find(":",F52))) -> 3 | I52: =if(G52>H52,1,if(H52>G52,2,"x")) -> 1 | J52: =iferror(HLOOKUP(I52,$C$1:$E$100,row(),true),"") -> 1.13 | K52: 3:3 | L52: 5:2 | M52: 2:2 | N52: 3:2 | O52: 6:2 | Q52: 3:0
...

Sheet állás
A1: Helyezés | B1: Név | C1: Pont
A2: =if(row()-1<=(columns(pont!$A$2:$O$2)-countblank(pont!$A$2:$O$2)),row()-1,"") -> 1 | B2: {=iferror(INDEX(pont!$B$1:$O$1,MATCH(C2,pont!$B$2:$O$2,0)),"")} -> Csiszi | C2: =iferror(large(pont!$B$2:$O$2,A2),"") -> 82.16
A3: =if(row()-1<=(columns(pont!$A$2:$O$2)-countblank(pont!$A$2:$O$2)),row()-1,"") -> 2 | B3: {=iferror(INDEX(pont!$B$1:$O$1,MATCH(C3,pont!$B$2:$O$2,0)),"")} -> Kinga | C3: =iferror(large(pont!$B$2:$O$2,A3),"") -> 81.62
A4: =if(row()-1<=(columns(pont!$A$2:$O$2)-countblank(pont!$A$2:$O$2)),row()-1,"") -> 3 | B4: {=iferror(INDEX(pont!$B$1:$O$1,MATCH(C4,pont!$B$2:$O$2,0)),"")} -> Benő | C4: =iferror(large(pont!$B$2:$O$2,A4),"") -> 79.04
A5: =if(row()-1<=(columns(pont!$A$2:$O$2)-countblank(pont!$A$2:$O$2)),row()-1,"") -> 4 | B5: {=iferror(INDEX(pont!$B$1:$O$1,MATCH(C5,pont!$B$2:$O$2,0)),"")} -> Tomi | C5: =iferror(large(pont!$B$2:$O$2,A5),"") -> 73.08
A6: =if(row()-1<=(columns(pont!$A$2:$O$2)-countblank(pont!$A$2:$O$2)),row()-1,"") -> 5 | B6: {=iferror(INDEX(pont!$B$1:$O$1,MATCH(C6,pont!$B$2:$O$2,0)),"")} -> Viki | C6: =iferror(large(pont!$B$2:$O$2,A6),"") -> 63.73
A7: =if(row()-1<=(columns(pont!$A$2:$O$2)-countblank(pont!$A$2:$O$2)),row()-1,"") -> 6 | B7: {=iferror(INDEX(pont!$B$1:$O$1,MATCH(C7,pont!$B$2:$O$2,0)),"")} -> Geri | C7: =iferror(large(pont!$B$2:$O$2,A7),"") -> 63.02
A8: =if(row()-1<=(columns(pont!$A$2:$O$2)-countblank(pont!$A$2:$O$2)),row()-1,"") -> 7 | B8: {=iferror(INDEX(pont!$B$1:$O$1,MATCH(C8,pont!$B$2:$O$2,0)),"")} -> Andris | C8: =iferror(large(pont!$B$2:$O$2,A8),"") -> 18.85
A9: =if(row()-1<=(columns(pont!$A$2:$O$2)-countblank(pont!$A$2:$O$2)),row()-1,"") | B9: {=iferror(INDEX(pont!$B$1:$O$1,MATCH(C9,pont!$B$2:$O$2,0)),"")} | C9: =iferror(large(pont!$B$2:$O$2,A9),"")
A10: =if(row()-1<=(columns(pont!$A$2:$O$2)-countblank(pont!$A$2:$O$2)),row()-1,"") | B10: {=iferror(INDEX(pont!$B$1:$O$1,MATCH(C10,pont!$B$2:$O$2,0)),"")} | C10: =iferror(large(pont!$B$2:$O$2,A10),"")
A11: =if(row()-1<=(columns(pont!$A$2:$O$2)-countblank(pont!$A$2:$O$2)),row()-1,"") | B11: {=iferror(INDEX(pont!$B$1:$O$1,MATCH(C11,pont!$B$2:$O$2,0)),"")} | C11: =iferror(large(pont!$B$2:$O$2,A11),"")
A12: =if(row()-1<=(columns(pont!$A$2:$O$2)-countblank(pont!$A$2:$O$2)),row()-1,"") | B12: {=iferror(INDEX(pont!$B$1:$O$1,MATCH(C12,pont!$B$2:$O$2,0)),"")} | C12: =iferror(large(pont!$B$2:$O$2,A12),"")
A13: =if(row()-1<=(columns(pont!$A$2:$O$2)-countblank(pont!$A$2:$O$2)),row()-1,"") | B13: {=iferror(INDEX(pont!$B$1:$O$1,MATCH(C13,pont!$B$2:$O$2,0)),"")} | C13: =iferror(large(pont!$B$2:$O$2,A13),"")
... A17: =if(row()-1<=(columns(pont!$A$2:$O$2)-countblank(pont!$A$2:$O$2)),row()-1,"") | B17: {=iferror(INDEX(pont!$B$1:$O$1,MATCH(C17,pont!$B$2:$O$2,0)),"")} | C17: =iferror(large(pont!$B$2:$O$2,A17),"")

Sheet pont
A1: IDE NE ÍRJ SEMMIT! | B1: =if(isblank(tipp!K1),"",tipp!K1) -> Csiszi | C1: =if(isblank(tipp!L1),"",tipp!L1) -> Viki | D1: =if(isblank(tipp!M1),"",tipp!M1) -> Kinga | E1: =if(isblank(tipp!N1),"",tipp!N1) -> Tomi | F1: =if(isblank(tipp!O1),"",tipp!O1) -> Benő | G1: =if(isblank(tipp!P1),"",tipp!P1) | H1: =if(isblank(tipp!Q1),"",tipp!Q1) -> Geri | I1: =if(isblank(tipp!R1),"",tipp!R1) -> Andris | ... M1: =if(isblank(tipp!V1),"",tipp!V1)
B2: =if(B1="","",sum(B3:B83)) -> 82.16 | C2: =if(C1="","",sum(C3:C83)) -> 63.73 | D2: =if(D1="","",sum(D3:D83)) -> 81.62 | E2: =if(E1="","",sum(E3:E83)) -> 73.08 | F2: =if(F1="","",sum(F3:F83)) -> 79.04 | G2: =if(G1="","",sum(G6:G83)) | H2: =if(H1="","",sum(H3:H83)) -> 63.02 | I2: =if(I1="","",sum(I3:I83)) -> 18.85 | J2: =if(J1="","",sum(J3:J83)) | K2: =if(K1="","",sum(K6:K83)) | L2: =if(L1="","",sum(L6:L83)) | M2: =if(M1="","",sum(M6:M83)) | N2: =if(N1="","",sum(N6:N83)) | O2: =if(O1="","",sum(O6:O83))
A3: aranyérmes tipp | B3: =if(B$1<>"",if(tipp!K2=pontozas!$B25,pontozas!$B$5,0)+if(countif(pontozas!$B$25:$D$27,tipp!K2)>0,pontozas!$B$4,0),"") -> 4 | C3: =if(C$1<>"",if(tipp!L2=pontozas!$B25,pontozas!$B$5,0)+if(countif(pontozas!$B$25:$D$27,tipp!L2)>0,pontozas!$B$4,0),"") -> 0 | D3: =if(D$1<>"",if(tipp!M2=pontozas!$B25,pontozas!$B$5,0)+if(countif(pontozas!$B$25:$D$27,tipp!M2)>0,pontozas!$B$4,0),"") -> 0 | E3: =if(E$1<>"",if(tipp!N2=pontozas!$B25,pontozas!$B$5,0)+if(countif(pontozas!$B$25:$D$27,tipp!N2)>0,pontozas!$B$4,0),"") -> 4 | F3: =if(F$1<>"",if(tipp!O2=pontozas!$B25,pontozas!$B$5,0)+if(countif(pontozas!$B$25:$D$27,tipp!O2)>0,pontozas!$B$4,0),"") -> 2 | G3: =if(G$1<>"",if(tipp!P2=pontozas!$B25,pontozas!$B$5,0)+if(countif(pontozas!$B$25:$D$27,tipp!P2)>0,pontozas!$B$4,0),"") | H3: =if(H$1<>"",if(tipp!Q2=pontozas!$B25,pontozas!$B$5,0)+if(countif(pontozas!$B$25:$D$27,tipp!Q2)>0,pontozas!$B$4,0),"") -> 0 | I3: =if(I$1<>"",if(tipp!R2=pontozas!$B25,pontozas!$B$5,0)+if(countif(pontozas!$B$25:$D$27,tipp!R2)>0,pontozas!$B$4,0),"") -> 0 | ... O3: =if(O$1<>"",if(tipp!X2=pontozas!$B25,pontozas!$B$5,0)+if(countif(pontozas!$B$25:$D$27,tipp!X2)>0,pontozas!$B$4,0),"")
A4: ezüstérmes tipp | B4: =if(B$1<>"",if(tipp!K3=pontozas!$B26,pontozas!$B$5,0)+if(countif(pontozas!$B$25:$D$27,tipp!K3)>0,pontozas!$B$4,0),"") -> 0 | C4: =if(C$1<>"",if(tipp!L3=pontozas!$B26,pontozas!$B$5,0)+if(countif(pontozas!$B$25:$D$27,tipp!L3)>0,pontozas!$B$4,0),"") -> 0 | D4: =if(D$1<>"",if(tipp!M3=pontozas!$B26,pontozas!$B$5,0)+if(countif(pontozas!$B$25:$D$27,tipp!M3)>0,pontozas!$B$4,0),"") -> 2 | E4: =if(E$1<>"",if(tipp!N3=pontozas!$B26,pontozas!$B$5,0)+if(countif(pontozas!$B$25:$D$27,tipp!N3)>0,pontozas!$B$4,0),"") -> 0 | F4: =if(F$1<>"",if(tipp!O3=pontozas!$B26,pontozas!$B$5,0)+if(countif(pontozas!$B$25:$D$27,tipp!O3)>0,pontozas!$B$4,0),"") -> 0 | G4: =if(G$1<>"",if(tipp!P3=pontozas!$B26,pontozas!$B$5,0)+if(countif(pontozas!$B$25:$D$27,tipp!P3)>0,pontozas!$B$4,0),"") | H4: =if(H$1<>"",if(tipp!Q3=pontozas!$B26,pontozas!$B$5,0)+if(countif(pontozas!$B$25:$D$27,tipp!Q3)>0,pontozas!$B$4,0),"") -> 0 | I4: =if(I$1<>"",if(tipp!R3=pontozas!$B26,pontozas!$B$5,0)+if(countif(pontozas!$B$25:$D$27,tipp!R3)>0,pontozas!$B$4,0),"") -> 0 | ... O4: =if(O$1<>"",if(tipp!X3=pontozas!$B26,pontozas!$B$5,0)+if(countif(pontozas!$B$25:$D$27,tipp!X3)>0,pontozas!$B$4,0),"")
A5: bronzérmes tipp | B5: =if(B$1<>"",if(tipp!K4=pontozas!$B27,pontozas!$B$5,0)+if(countif(pontozas!$B$25:$D$27,tipp!K4)>0,pontozas!$B$4,0),"") -> 0 | C5: =if(C$1<>"",if(tipp!L4=pontozas!$B27,pontozas!$B$5,0)+if(countif(pontozas!$B$25:$D$27,tipp!L4)>0,pontozas!$B$4,0),"") -> 0 | D5: =if(D$1<>"",if(tipp!M4=pontozas!$B27,pontozas!$B$5,0)+if(countif(pontozas!$B$25:$D$27,tipp!M4)>0,pontozas!$B$4,0),"") -> 0 | E5: =if(E$1<>"",if(tipp!N4=pontozas!$B27,pontozas!$B$5,0)+if(countif(pontozas!$B$25:$D$27,tipp!N4)>0,pontozas!$B$4,0),"") -> 0 | F5: =if(F$1<>"",if(tipp!O4=pontozas!$B27,pontozas!$B$5,0)+if(countif(pontozas!$B$25:$D$27,tipp!O4)>0,pontozas!$B$4,0),"") -> 2 | G5: =if(G$1<>"",if(tipp!P4=pontozas!$B27,pontozas!$B$5,0)+if(countif(pontozas!$B$25:$D$27,tipp!P4)>0,pontozas!$B$4,0),"") | H5: =if(H$1<>"",if(tipp!Q4=pontozas!$B27,pontozas!$B$5,0)+if(countif(pontozas!$B$25:$D$27,tipp!Q4)>0,pontozas!$B$4,0),"") -> 0 | I5: =if(I$1<>"",if(tipp!R4=pontozas!$B27,pontozas!$B$5,0)+if(countif(pontozas!$B$25:$D$27,tipp!R4)>0,pontozas!$B$4,0),"") -> 0 | ... O5: =if(O$1<>"",if(tipp!X4=pontozas!$B27,pontozas!$B$5,0)+if(countif(pontozas!$B$25:$D$27,tipp!X4)>0,pontozas!$B$4,0),"")
A6: =CONCATENATE(tipp!A5&" : "&tipp!B5) -> Russia : France | B6: =if(B$1<>"",iferror(if(if(left(tipp!K5,find(":",tipp!K5)-1)>right(tipp!K5,(len(tipp!K5)-find(":",tipp!K5))),1,if(right(tipp!K5,(len(tipp!K5)-find(":",tipp!K5)))>left(tipp!K5,find(":",tipp!K5)-1),2,"x"))=tipp!$I5,tipp!$J5*pontozas!$B$1)+if(left(tipp!K5,find(":",tipp!K5)-1)-right(tipp!K5,(len(tipp!K5)-find(":",tipp!K5)))=tipp!$G5-tipp!$H5,pontozas!$B$2,0)+if(tipp!K5=tipp!$F5,pontozas!$B$3),""),"") -> 1.08 | C6: =if(C$1<>"",iferror(if(if(left(tipp!L5,find(":",tipp!L5)-1)>right(tipp!L5,(len(tipp!L5)-find(":",tipp!L5))),1,if(right(tipp!L5,(len(tipp!L5)-find(":",tipp!L5)))>left(tipp!L5,find(":",tipp!L5)-1),2,"x"))=tipp!$I5,tipp!$J5*pontozas!$B$1)+if(left(tipp!L5,find(":",tipp!L5)-1)-right(tipp!L5,(len(tipp!L5)-find(":",tipp!L5)))=tipp!$G5-tipp!$H5,pontozas!$B$2,0)+if(tipp!L5=tipp!$F5,pontozas!$B$3),""),"") -> 1.08 | D6: =if(D$1<>"",iferror(if(if(left(tipp!M5,find(":",tipp!M5)-1)>right(tipp!M5,(len(tipp!M5)-find(":",tipp!M5))),1,if(right(tipp!M5,(len(tipp!M5)-find(":",tipp!M5)))>left(tipp!M5,find(":",tipp!M5)-1),2,"x"))=tipp!$I5,tipp!$J5*pontozas!$B$1)+if(left(tipp!M5,find(":",tipp!M5)-1)-right(tipp!M5,(len(tipp!M5)-find(":",tipp!M5)))=tipp!$G5-tipp!$H5,pontozas!$B$2,0)+if(tipp!M5=tipp!$F5,pontozas!$B$3),""),"") -> 1.08 | E6: =if(E$1<>"",iferror(if(if(left(tipp!N5,find(":",tipp!N5)-1)>right(tipp!N5,(len(tipp!N5)-find(":",tipp!N5))),1,if(right(tipp!N5,(len(tipp!N5)-find(":",tipp!N5)))>left(tipp!N5,find(":",tipp!N5)-1),2,"x"))=tipp!$I5,tipp!$J5*pontozas!$B$1)+if(left(tipp!N5,find(":",tipp!N5)-1)-right(tipp!N5,(len(tipp!N5)-find(":",tipp!N5)))=tipp!$G5-tipp!$H5,pontozas!$B$2,0)+if(tipp!N5=tipp!$F5,pontozas!$B$3),""),"") -> 1.08 | F6: =if(F$1<>"",iferror(if(if(left(tipp!O5,find(":",tipp!O5)-1)>right(tipp!O5,(len(tipp!O5)-find(":",tipp!O5))),1,if(right(tipp!O5,(len(tipp!O5)-find(":",tipp!O5)))>left(tipp!O5,find(":",tipp!O5)-1),2,"x"))=tipp!$I5,tipp!$J5*pontozas!$B$1)+if(left(tipp!O5,find(":",tipp!O5)-1)-right(tipp!O5,(len(tipp!O5)-find(":",tipp!O5)))=tipp!$G5-tipp!$H5,pontozas!$B$2,0)+if(tipp!O5=tipp!$F5,pontozas!$B$3),""),"") -> 1.08 | G6: =if(G$1<>"",iferror(if(if(left(tipp!P5,find(":",tipp!P5)-1)>right(tipp!P5,(len(tipp!P5)-find(":",tipp!P5))),1,if(right(tipp!P5,(len(tipp!P5)-find(":",tipp!P5)))>left(tipp!P5,find(":",tipp!P5)-1),2,"x"))=tipp!$I5,tipp!$J5*pontozas!$B$1)+if(left(tipp!P5,find(":",tipp!P5)-1)-right(tipp!P5,(len(tipp!P5)-find(":",tipp!P5)))=tipp!$G5-tipp!$H5,pontozas!$B$2,0)+if(tipp!P5=tipp!$F5,pontozas!$B$3),""),"") | H6: =if(H$1<>"",iferror(if(if(left(tipp!Q5,find(":",tipp!Q5)-1)>right(tipp!Q5,(len(tipp!Q5)-find(":",tipp!Q5))),1,if(right(tipp!Q5,(len(tipp!Q5)-find(":",tipp!Q5)))>left(tipp!Q5,find(":",tipp!Q5)-1),2,"x"))=tipp!$I5,tipp!$J5*pontozas!$B$1)+if(left(tipp!Q5,find(":",tipp!Q5)-1)-right(tipp!Q5,(len(tipp!Q5)-find(":",tipp!Q5)))=tipp!$G5-tipp!$H5,pontozas!$B$2,0)+if(tipp!Q5=tipp!$F5,pontozas!$B$3),""),"") -> 1.08 | I6: =if(I$1<>"",iferror(if(if(left(tipp!R5,find(":",tipp!R5)-1)>right(tipp!R5,(len(tipp!R5)-find(":",tipp!R5))),1,if(right(tipp!R5,(len(tipp!R5)-find(":",tipp!R5)))>left(tipp!R5,find(":",tipp!R5)-1),2,"x"))=tipp!$I5,tipp!$J5*pontozas!$B$1)+if(left(tipp!R5,find(":",tipp!R5)-1)-right(tipp!R5,(len(tipp!R5)-find(":",tipp!R5)))=tipp!$G5-tipp!$H5,pontozas!$B$2,0)+if(tipp!R5=tipp!$F5,pontozas!$B$3),""),"") -> 1.08 | ... O6: =if(O$1<>"",iferror(if(if(left(tipp!X5,find(":",tipp!X5)-1)>right(tipp!X5,(len(tipp!X5)-find(":",tipp!X5))),1,if(right(tipp!X5,(len(tipp!X5)-find(":",tipp!X5)))>left(tipp!X5,find(":",tipp!X5)-1),2,"x"))=tipp!$I5,tipp!$J5*pontozas!$B$1)+if(left(tipp!X5,find(":",tipp!X5)-1)-right(tipp!X5,(len(tipp!X5)-find(":",tipp!X5)))=tipp!$G5-tipp!$H5,pontozas!$B$2,0)+if(tipp!X5=tipp!$F5,pontozas!$B$3),""),"")
A7: =CONCATENATE(tipp!A6&" : "&tipp!B6) -> Sweden : Belarus | B7: =if(B$1<>"",iferror(if(if(left(tipp!K6,find(":",tipp!K6)-1)>right(tipp!K6,(len(tipp!K6)-find(":",tipp!K6))),1,if(right(tipp!K6,(len(tipp!K6)-find(":",tipp!K6)))>left(tipp!K6,find(":",tipp!K6)-1),2,"x"))=tipp!$I6,tipp!$J6*pontozas!$B$1)+if(left(tipp!K6,find(":",tipp!K6)-1)-right(tipp!K6,(len(tipp!K6)-find(":",tipp!K6)))=tipp!$G6-tipp!$H6,pontozas!$B$2,0)+if(tipp!K6=tipp!$F6,pontozas!$B$3),""),"") -> 1.17 | C7: =if(C$1<>"",iferror(if(if(left(tipp!L6,find(":",tipp!L6)-1)>right(tipp!L6,(len(tipp!L6)-find(":",tipp!L6))),1,if(right(tipp!L6,(len(tipp!L6)-find(":",tipp!L6)))>left(tipp!L6,find(":",tipp!L6)-1),2,"x"))=tipp!$I6,tipp!$J6*pontozas!$B$1)+if(left(tipp!L6,find(":",tipp!L6)-1)-right(tipp!L6,(len(tipp!L6)-find(":",tipp!L6)))=tipp!$G6-tipp!$H6,pontozas!$B$2,0)+if(tipp!L6=tipp!$F6,pontozas!$B$3),""),"") -> 1.17 | D7: =if(D$1<>"",iferror(if(if(left(tipp!M6,find(":",tipp!M6)-1)>right(tipp!M6,(len(tipp!M6)-find(":",tipp!M6))),1,if(right(tipp!M6,(len(tipp!M6)-find(":",tipp!M6)))>left(tipp!M6,find(":",tipp!M6)-1),2,"x"))=tipp!$I6,tipp!$J6*pontozas!$B$1)+if(left(tipp!M6,find(":",tipp!M6)-1)-right(tipp!M6,(len(tipp!M6)-find(":",tipp!M6)))=tipp!$G6-tipp!$H6,pontozas!$B$2,0)+if(tipp!M6=tipp!$F6,pontozas!$B$3),""),"") -> 1.17 | E7: =if(E$1<>"",iferror(if(if(left(tipp!N6,find(":",tipp!N6)-1)>right(tipp!N6,(len(tipp!N6)-find(":",tipp!N6))),1,if(right(tipp!N6,(len(tipp!N6)-find(":",tipp!N6)))>left(tipp!N6,find(":",tipp!N6)-1),2,"x"))=tipp!$I6,tipp!$J6*pontozas!$B$1)+if(left(tipp!N6,find(":",tipp!N6)-1)-right(tipp!N6,(len(tipp!N6)-find(":",tipp!N6)))=tipp!$G6-tipp!$H6,pontozas!$B$2,0)+if(tipp!N6=tipp!$F6,pontozas!$B$3),""),"") -> 1.17 | F7: =if(F$1<>"",iferror(if(if(left(tipp!O6,find(":",tipp!O6)-1)>right(tipp!O6,(len(tipp!O6)-find(":",tipp!O6))),1,if(right(tipp!O6,(len(tipp!O6)-find(":",tipp!O6)))>left(tipp!O6,find(":",tipp!O6)-1),2,"x"))=tipp!$I6,tipp!$J6*pontozas!$B$1)+if(left(tipp!O6,find(":",tipp!O6)-1)-right(tipp!O6,(len(tipp!O6)-find(":",tipp!O6)))=tipp!$G6-tipp!$H6,pontozas!$B$2,0)+if(tipp!O6=tipp!$F6,pontozas!$B$3),""),"") -> 3.17 | G7: =if(G$1<>"",iferror(if(if(left(tipp!P6,find(":",tipp!P6)-1)>right(tipp!P6,(len(tipp!P6)-find(":",tipp!P6))),1,if(right(tipp!P6,(len(tipp!P6)-find(":",tipp!P6)))>left(tipp!P6,find(":",tipp!P6)-1),2,"x"))=tipp!$I6,tipp!$J6*pontozas!$B$1)+if(left(tipp!P6,find(":",tipp!P6)-1)-right(tipp!P6,(len(tipp!P6)-find(":",tipp!P6)))=tipp!$G6-tipp!$H6,pontozas!$B$2,0)+if(tipp!P6=tipp!$F6,pontozas!$B$3),""),"") | H7: =if(H$1<>"",iferror(if(if(left(tipp!Q6,find(":",tipp!Q6)-1)>right(tipp!Q6,(len(tipp!Q6)-find(":",tipp!Q6))),1,if(right(tipp!Q6,(len(tipp!Q6)-find(":",tipp!Q6)))>left(tipp!Q6,find(":",tipp!Q6)-1),2,"x"))=tipp!$I6,tipp!$J6*pontozas!$B$1)+if(left(tipp!Q6,find(":",tipp!Q6)-1)-right(tipp!Q6,(len(tipp!Q6)-find(":",tipp!Q6)))=tipp!$G6-tipp!$H6,pontozas!$B$2,0)+if(tipp!Q6=tipp!$F6,pontozas!$B$3),""),"") -> 0 | I7: =if(I$1<>"",iferror(if(if(left(tipp!R6,find(":",tipp!R6)-1)>right(tipp!R6,(len(tipp!R6)-find(":",tipp!R6))),1,if(right(tipp!R6,(len(tipp!R6)-find(":",tipp!R6)))>left(tipp!R6,find(":",tipp!R6)-1),2,"x"))=tipp!$I6,tipp!$J6*pontozas!$B$1)+if(left(tipp!R6,find(":",tipp!R6)-1)-right(tipp!R6,(len(tipp!R6)-find(":",tipp!R6)))=tipp!$G6-tipp!$H6,pontozas!$B$2,0)+if(tipp!R6=tipp!$F6,pontozas!$B$3),""),"") -> 1.17 | ... O7: =if(O$1<>"",iferror(if(if(left(tipp!X6,find(":",tipp!X6)-1)>right(tipp!X6,(len(tipp!X6)-find(":",tipp!X6))),1,if(right(tipp!X6,(len(tipp!X6)-find(":",tipp!X6)))>left(tipp!X6,find(":",tipp!X6)-1),2,"x"))=tipp!$I6,tipp!$J6*pontozas!$B$1)+if(left(tipp!X6,find(":",tipp!X6)-1)-right(tipp!X6,(len(tipp!X6)-find(":",tipp!X6)))=tipp!$G6-tipp!$H6,pontozas!$B$2,0)+if(tipp!X6=tipp!$F6,pontozas!$B$3),""),"")
A8: =CONCATENATE(tipp!A7&" : "&tipp!B7) -> United States : Canada | B8: =if(B$1<>"",iferror(if(if(left(tipp!K7,find(":",tipp!K7)-1)>right(tipp!K7,(len(tipp!K7)-find(":",tipp!K7))),1,if(right(tipp!K7,(len(tipp!K7)-find(":",tipp!K7)))>left(tipp!K7,find(":",tipp!K7)-1),2,"x"))=tipp!$I7,tipp!$J7*pontozas!$B$1)+if(left(tipp!K7,find(":",tipp!K7)-1)-right(tipp!K7,(len(tipp!K7)-find(":",tipp!K7)))=tipp!$G7-tipp!$H7,pontozas!$B$2,0)+if(tipp!K7=tipp!$F7,pontozas!$B$3),""),"") -> 0 | C8: =if(C$1<>"",iferror(if(if(left(tipp!L7,find(":",tipp!L7)-1)>right(tipp!L7,(len(tipp!L7)-find(":",tipp!L7))),1,if(right(tipp!L7,(len(tipp!L7)-find(":",tipp!L7)))>left(tipp!L7,find(":",tipp!L7)-1),2,"x"))=tipp!$I7,tipp!$J7*pontozas!$B$1)+if(left(tipp!L7,find(":",tipp!L7)-1)-right(tipp!L7,(len(tipp!L7)-find(":",tipp!L7)))=tipp!$G7-tipp!$H7,pontozas!$B$2,0)+if(tipp!L7=tipp!$F7,pontozas!$B$3),""),"") -> 0 | D8: =if(D$1<>"",iferror(if(if(left(tipp!M7,find(":",tipp!M7)-1)>right(tipp!M7,(len(tipp!M7)-find(":",tipp!M7))),1,if(right(tipp!M7,(len(tipp!M7)-find(":",tipp!M7)))>left(tipp!M7,find(":",tipp!M7)-1),2,"x"))=tipp!$I7,tipp!$J7*pontozas!$B$1)+if(left(tipp!M7,find(":",tipp!M7)-1)-right(tipp!M7,(len(tipp!M7)-find(":",tipp!M7)))=tipp!$G7-tipp!$H7,pontozas!$B$2,0)+if(tipp!M7=tipp!$F7,pontozas!$B$3),""),"") -> 0 | E8: =if(E$1<>"",iferror(if(if(left(tipp!N7,find(":",tipp!N7)-1)>right(tipp!N7,(len(tipp!N7)-find(":",tipp!N7))),1,if(right(tipp!N7,(len(tipp!N7)-find(":",tipp!N7)))>left(tipp!N7,find(":",tipp!N7)-1),2,"x"))=tipp!$I7,tipp!$J7*pontozas!$B$1)+if(left(tipp!N7,find(":",tipp!N7)-1)-right(tipp!N7,(len(tipp!N7)-find(":",tipp!N7)))=tipp!$G7-tipp!$H7,pontozas!$B$2,0)+if(tipp!N7=tipp!$F7,pontozas!$B$3),""),"") -> 0 | F8: =if(F$1<>"",iferror(if(if(left(tipp!O7,find(":",tipp!O7)-1)>right(tipp!O7,(len(tipp!O7)-find(":",tipp!O7))),1,if(right(tipp!O7,(len(tipp!O7)-find(":",tipp!O7)))>left(tipp!O7,find(":",tipp!O7)-1),2,"x"))=tipp!$I7,tipp!$J7*pontozas!$B$1)+if(left(tipp!O7,find(":",tipp!O7)-1)-right(tipp!O7,(len(tipp!O7)-find(":",tipp!O7)))=tipp!$G7-tipp!$H7,pontozas!$B$2,0)+if(tipp!O7=tipp!$F7,pontozas!$B$3),""),"") -> 6 | G8: =if(G$1<>"",iferror(if(if(left(tipp!P7,find(":",tipp!P7)-1)>right(tipp!P7,(len(tipp!P7)-find(":",tipp!P7))),1,if(right(tipp!P7,(len(tipp!P7)-find(":",tipp!P7)))>left(tipp!P7,find(":",tipp!P7)-1),2,"x"))=tipp!$I7,tipp!$J7*pontozas!$B$1)+if(left(tipp!P7,find(":",tipp!P7)-1)-right(tipp!P7,(len(tipp!P7)-find(":",tipp!P7)))=tipp!$G7-tipp!$H7,pontozas!$B$2,0)+if(tipp!P7=tipp!$F7,pontozas!$B$3),""),"") | H8: =if(H$1<>"",iferror(if(if(left(tipp!Q7,find(":",tipp!Q7)-1)>right(tipp!Q7,(len(tipp!Q7)-find(":",tipp!Q7))),1,if(right(tipp!Q7,(len(tipp!Q7)-find(":",tipp!Q7)))>left(tipp!Q7,find(":",tipp!Q7)-1),2,"x"))=tipp!$I7,tipp!$J7*pontozas!$B$1)+if(left(tipp!Q7,find(":",tipp!Q7)-1)-right(tipp!Q7,(len(tipp!Q7)-find(":",tipp!Q7)))=tipp!$G7-tipp!$H7,pontozas!$B$2,0)+if(tipp!Q7=tipp!$F7,pontozas!$B$3),""),"") -> 6 | I8: =if(I$1<>"",iferror(if(if(left(tipp!R7,find(":",tipp!R7)-1)>right(tipp!R7,(len(tipp!R7)-find(":",tipp!R7))),1,if(right(tipp!R7,(len(tipp!R7)-find(":",tipp!R7)))>left(tipp!R7,find(":",tipp!R7)-1),2,"x"))=tipp!$I7,tipp!$J7*pontozas!$B$1)+if(left(tipp!R7,find(":",tipp!R7)-1)-right(tipp!R7,(len(tipp!R7)-find(":",tipp!R7)))=tipp!$G7-tipp!$H7,pontozas!$B$2,0)+if(tipp!R7=tipp!$F7,pontozas!$B$3),""),"") -> 0 | ... O8: =if(O$1<>"",iferror(if(if(left(tipp!X7,find(":",tipp!X7)-1)>right(tipp!X7,(len(tipp!X7)-find(":",tipp!X7))),1,if(right(tipp!X7,(len(tipp!X7)-find(":",tipp!X7)))>left(tipp!X7,find(":",tipp!X7)-1),2,"x"))=tipp!$I7,tipp!$J7*pontozas!$B$1)+if(left(tipp!X7,find(":",tipp!X7)-1)-right(tipp!X7,(len(tipp!X7)-find(":",tipp!X7)))=tipp!$G7-tipp!$H7,pontozas!$B$2,0)+if(tipp!X7=tipp!$F7,pontozas!$B$3),""),"")
A9: =CONCATENATE(tipp!A8&" : "&tipp!B8) -> Germany : Denmark | B9: =if(B$1<>"",iferror(if(if(left(tipp!K8,find(":",tipp!K8)-1)>right(tipp!K8,(len(tipp!K8)-find(":",tipp!K8))),1,if(right(tipp!K8,(len(tipp!K8)-find(":",tipp!K8)))>left(tipp!K8,find(":",tipp!K8)-1),2,"x"))=tipp!$I8,tipp!$J8*pontozas!$B$1)+if(left(tipp!K8,find(":",tipp!K8)-1)-right(tipp!K8,(len(tipp!K8)-find(":",tipp!K8)))=tipp!$G8-tipp!$H8,pontozas!$B$2,0)+if(tipp!K8=tipp!$F8,pontozas!$B$3),""),"") -> 0 | C9: =if(C$1<>"",iferror(if(if(left(tipp!L8,find(":",tipp!L8)-1)>right(tipp!L8,(len(tipp!L8)-find(":",tipp!L8))),1,if(right(tipp!L8,(len(tipp!L8)-find(":",tipp!L8)))>left(tipp!L8,find(":",tipp!L8)-1),2,"x"))=tipp!$I8,tipp!$J8*pontozas!$B$1)+if(left(tipp!L8,find(":",tipp!L8)-1)-right(tipp!L8,(len(tipp!L8)-find(":",tipp!L8)))=tipp!$G8-tipp!$H8,pontozas!$B$2,0)+if(tipp!L8=tipp!$F8,pontozas!$B$3),""),"") -> 0 | D9: =if(D$1<>"",iferror(if(if(left(tipp!M8,find(":",tipp!M8)-1)>right(tipp!M8,(len(tipp!M8)-find(":",tipp!M8))),1,if(right(tipp!M8,(len(tipp!M8)-find(":",tipp!M8)))>left(tipp!M8,find(":",tipp!M8)-1),2,"x"))=tipp!$I8,tipp!$J8*pontozas!$B$1)+if(left(tipp!M8,find(":",tipp!M8)-1)-right(tipp!M8,(len(tipp!M8)-find(":",tipp!M8)))=tipp!$G8-tipp!$H8,pontozas!$B$2,0)+if(tipp!M8=tipp!$F8,pontozas!$B$3),""),"") -> 0 | E9: =if(E$1<>"",iferror(if(if(left(tipp!N8,find(":",tipp!N8)-1)>right(tipp!N8,(len(tipp!N8)-find(":",tipp!N8))),1,if(right(tipp!N8,(len(tipp!N8)-find(":",tipp!N8)))>left(tipp!N8,find(":",tipp!N8)-1),2,"x"))=tipp!$I8,tipp!$J8*pontozas!$B$1)+if(left(tipp!N8,find(":",tipp!N8)-1)-right(tipp!N8,(len(tipp!N8)-find(":",tipp!N8)))=tipp!$G8-tipp!$H8,pontozas!$B$2,0)+if(tipp!N8=tipp!$F8,pontozas!$B$3),""),"") -> 6 | F9: =if(F$1<>"",iferror(if(if(left(tipp!O8,find(":",tipp!O8)-1)>right(tipp!O8,(len(tipp!O8)-find(":",tipp!O8))),1,if(right(tipp!O8,(len(tipp!O8)-find(":",tipp!O8)))>left(tipp!O8,find(":",tipp!O8)-1),2,"x"))=tipp!$I8,tipp!$J8*pontozas!$B$1)+if(left(tipp!O8,find(":",tipp!O8)-1)-right(tipp!O8,(len(tipp!O8)-find(":",tipp!O8)))=tipp!$G8-tipp!$H8,pontozas!$B$2,0)+if(tipp!O8=tipp!$F8,pontozas!$B$3),""),"") -> 0 | G9: =if(G$1<>"",iferror(if(if(left(tipp!P7,find(":",tipp!P7)-1)>right(tipp!P7,(len(tipp!P7)-find(":",tipp!P7))),1,if(right(tipp!P7,(len(tipp!P7)-find(":",tipp!P7)))>left(tipp!P7,find(":",tipp!P7)-1),2,"x"))=tipp!$I8,tipp!$J8*pontozas!$B$1)+if(left(tipp!P7,find(":",tipp!P7)-1)-right(tipp!P7,(len(tipp!P7)-find(":",tipp!P7)))=tipp!$G8-tipp!$H8,pontozas!$B$2,0)+if(tipp!P7=tipp!$F8,pontozas!$B$3),""),"") | H9: =if(H$1<>"",iferror(if(if(left(tipp!Q8,find(":",tipp!Q8)-1)>right(tipp!Q8,(len(tipp!Q8)-find(":",tipp!Q8))),1,if(right(tipp!Q8,(len(tipp!Q8)-find(":",tipp!Q8)))>left(tipp!Q8,find(":",tipp!Q8)-1),2,"x"))=tipp!$I8,tipp!$J8*pontozas!$B$1)+if(left(tipp!Q8,find(":",tipp!Q8)-1)-right(tipp!Q8,(len(tipp!Q8)-find(":",tipp!Q8)))=tipp!$G8-tipp!$H8,pontozas!$B$2,0)+if(tipp!Q8=tipp!$F8,pontozas!$B$3),""),"") -> 0 | I9: =if(I$1<>"",iferror(if(if(left(tipp!R8,find(":",tipp!R8)-1)>right(tipp!R8,(len(tipp!R8)-find(":",tipp!R8))),1,if(right(tipp!R8,(len(tipp!R8)-find(":",tipp!R8)))>left(tipp!R8,find(":",tipp!R8)-1),2,"x"))=tipp!$I8,tipp!$J8*pontozas!$B$1)+if(left(tipp!R8,find(":",tipp!R8)-1)-right(tipp!R8,(len(tipp!R8)-find(":",tipp!R8)))=tipp!$G8-tipp!$H8,pontozas!$B$2,0)+if(tipp!R8=tipp!$F8,pontozas!$B$3),""),"") -> 0 | J9: =if(J$1<>"",iferror(if(if(left(tipp!S8,find(":",tipp!S8)-1)>right(tipp!S8,(len(tipp!S8)-find(":",tipp!S8))),1,if(right(tipp!S8,(len(tipp!S8)-find(":",tipp!S8)))>left(tipp!S8,find(":",tipp!S8)-1),2,"x"))=tipp!$I8,tipp!$J8*pontozas!$B$1)+if(left(tipp!S8,find(":",tipp!S8)-1)-right(tipp!S8,(len(tipp!S8)-find(":",tipp!S8)))=tipp!$G8-tipp!$H8,pontozas!$B$2,0)+if(tipp!S8=tipp!$F8,pontozas!$B$3),""),"") | K9: =if(K$1<>"",iferror(if(if(left(tipp!T8,find(":",tipp!T8)-1)>right(tipp!T8,(len(tipp!T8)-find(":",tipp!T8))),1,if(right(tipp!T8,(len(tipp!T8)-find(":",tipp!T8)))>left(tipp!T8,find(":",tipp!T8)-1),2,"x"))=tipp!$I8,tipp!$J8*pontozas!$B$1)+if(left(tipp!T8,find(":",tipp!T8)-1)-right(tipp!T8,(len(tipp!T8)-find(":",tipp!T8)))=tipp!$G8-tipp!$H8,pontozas!$B$2,0)+if(tipp!T8=tipp!$F8,pontozas!$B$3),""),"") | L9: =if(L$1<>"",iferror(if(if(left(tipp!U8,find(":",tipp!U8)-1)>right(tipp!U8,(len(tipp!U8)-find(":",tipp!U8))),1,if(right(tipp!U8,(len(tipp!U8)-find(":",tipp!U8)))>left(tipp!U8,find(":",tipp!U8)-1),2,"x"))=tipp!$I8,tipp!$J8*pontozas!$B$1)+if(left(tipp!U8,find(":",tipp!U8)-1)-right(tipp!U8,(len(tipp!U8)-find(":",tipp!U8)))=tipp!$G8-tipp!$H8,pontozas!$B$2,0)+if(tipp!U8=tipp!$F8,pontozas!$B$3),""),"") | M9: =if(M$1<>"",iferror(if(if(left(tipp!V8,find(":",tipp!V8)-1)>right(tipp!V8,(len(tipp!V8)-find(":",tipp!V8))),1,if(right(tipp!V8,(len(tipp!V8)-find(":",tipp!V8)))>left(tipp!V8,find(":",tipp!V8)-1),2,"x"))=tipp!$I8,tipp!$J8*pontozas!$B$1)+if(left(tipp!V8,find(":",tipp!V8)-1)-right(tipp!V8,(len(tipp!V8)-find(":",tipp!V8)))=tipp!$G8-tipp!$H8,pontozas!$B$2,0)+if(tipp!V8=tipp!$F8,pontozas!$B$3),""),"") | N9: =if(N$1<>"",iferror(if(if(left(tipp!W8,find(":",tipp!W8)-1)>right(tipp!W8,(len(tipp!W8)-find(":",tipp!W8))),1,if(right(tipp!W8,(len(tipp!W8)-find(":",tipp!W8)))>left(tipp!W8,find(":",tipp!W8)-1),2,"x"))=tipp!$I8,tipp!$J8*pontozas!$B$1)+if(left(tipp!W8,find(":",tipp!W8)-1)-right(tipp!W8,(len(tipp!W8)-find(":",tipp!W8)))=tipp!$G8-tipp!$H8,pontozas!$B$2,0)+if(tipp!W8=tipp!$F8,pontozas!$B$3),""),"") | O9: =if(O$1<>"",iferror(if(if(left(tipp!X8,find(":",tipp!X8)-1)>right(tipp!X8,(len(tipp!X8)-find(":",tipp!X8))),1,if(right(tipp!X8,(len(tipp!X8)-find(":",tipp!X8)))>left(tipp!X8,find(":",tipp!X8)-1),2,"x"))=tipp!$I8,tipp!$J8*pontozas!$B$1)+if(left(tipp!X8,find(":",tipp!X8)-1)-right(tipp!X8,(len(tipp!X8)-find(":",tipp!X8)))=tipp!$G8-tipp!$H8,pontozas!$B$2,0)+if(tipp!X8=tipp!$F8,pontozas!$B$3),""),"")
A10: =CONCATENATE(tipp!A9&" : "&tipp!B9) -> Switzerland : Austria | B10: =if(B$1<>"",iferror(if(if(left(tipp!K9,find(":",tipp!K9)-1)>right(tipp!K9,(len(tipp!K9)-find(":",tipp!K9))),1,if(right(tipp!K9,(len(tipp!K9)-find(":",tipp!K9)))>left(tipp!K9,find(":",tipp!K9)-1),2,"x"))=tipp!$I9,tipp!$J9*pontozas!$B$1)+if(left(tipp!K9,find(":",tipp!K9)-1)-right(tipp!K9,(len(tipp!K9)-find(":",tipp!K9)))=tipp!$G9-tipp!$H9,pontozas!$B$2,0)+if(tipp!K9=tipp!$F9,pontozas!$B$3),""),"") -> 0 | C10: =if(C$1<>"",iferror(if(if(left(tipp!L9,find(":",tipp!L9)-1)>right(tipp!L9,(len(tipp!L9)-find(":",tipp!L9))),1,if(right(tipp!L9,(len(tipp!L9)-find(":",tipp!L9)))>left(tipp!L9,find(":",tipp!L9)-1),2,"x"))=tipp!$I9,tipp!$J9*pontozas!$B$1)+if(left(tipp!L9,find(":",tipp!L9)-1)-right(tipp!L9,(len(tipp!L9)-find(":",tipp!L9)))=tipp!$G9-tipp!$H9,pontozas!$B$2,0)+if(tipp!L9=tipp!$F9,pontozas!$B$3),""),"") -> 0 | D10: =if(D$1<>"",iferror(if(if(left(tipp!M9,find(":",tipp!M9)-1)>right(tipp!M9,(len(tipp!M9)-find(":",tipp!M9))),1,if(right(tipp!M9,(len(tipp!M9)-find(":",tipp!M9)))>left(tipp!M9,find(":",tipp!M9)-1),2,"x"))=tipp!$I9,tipp!$J9*pontozas!$B$1)+if(left(tipp!M9,find(":",tipp!M9)-1)-right(tipp!M9,(len(tipp!M9)-find(":",tipp!M9)))=tipp!$G9-tipp!$H9,pontozas!$B$2,0)+if(tipp!M9=tipp!$F9,pontozas!$B$3),""),"") -> 8 | E10: =if(E$1<>"",iferror(if(if(left(tipp!N9,find(":",tipp!N9)-1)>right(tipp!N9,(len(tipp!N9)-find(":",tipp!N9))),1,if(right(tipp!N9,(len(tipp!N9)-find(":",tipp!N9)))>left(tipp!N9,find(":",tipp!N9)-1),2,"x"))=tipp!$I9,tipp!$J9*pontozas!$B$1)+if(left(tipp!N9,find(":",tipp!N9)-1)-right(tipp!N9,(len(tipp!N9)-find(":",tipp!N9)))=tipp!$G9-tipp!$H9,pontozas!$B$2,0)+if(tipp!N9=tipp!$F9,pontozas!$B$3),""),"") -> 0 | F10: =if(F$1<>"",iferror(if(if(left(tipp!O9,find(":",tipp!O9)-1)>right(tipp!O9,(len(tipp!O9)-find(":",tipp!O9))),1,if(right(tipp!O9,(len(tipp!O9)-find(":",tipp!O9)))>left(tipp!O9,find(":",tipp!O9)-1),2,"x"))=tipp!$I9,tipp!$J9*pontozas!$B$1)+if(left(tipp!O9,find(":",tipp!O9)-1)-right(tipp!O9,(len(tipp!O9)-find(":",tipp!O9)))=tipp!$G9-tipp!$H9,pontozas!$B$2,0)+if(tipp!O9=tipp!$F9,pontozas!$B$3),""),"") -> 0 | G10: =if(G$1<>"",iferror(if(if(left(tipp!P9,find(":",tipp!P9)-1)>right(tipp!P9,(len(tipp!P9)-find(":",tipp!P9))),1,if(right(tipp!P9,(len(tipp!P9)-find(":",tipp!P9)))>left(tipp!P9,find(":",tipp!P9)-1),2,"x"))=tipp!$I9,tipp!$J9*pontozas!$B$1)+if(left(tipp!P9,find(":",tipp!P9)-1)-right(tipp!P9,(len(tipp!P9)-find(":",tipp!P9)))=tipp!$G9-tipp!$H9,pontozas!$B$2,0)+if(tipp!P9=tipp!$F9,pontozas!$B$3),""),"") | H10: =if(H$1<>"",iferror(if(if(left(tipp!Q9,find(":",tipp!Q9)-1)>right(tipp!Q9,(len(tipp!Q9)-find(":",tipp!Q9))),1,if(right(tipp!Q9,(len(tipp!Q9)-find(":",tipp!Q9)))>left(tipp!Q9,find(":",tipp!Q9)-1),2,"x"))=tipp!$I9,tipp!$J9*pontozas!$B$1)+if(left(tipp!Q9,find(":",tipp!Q9)-1)-right(tipp!Q9,(len(tipp!Q9)-find(":",tipp!Q9)))=tipp!$G9-tipp!$H9,pontozas!$B$2,0)+if(tipp!Q9=tipp!$F9,pontozas!$B$3),""),"") -> 0 | I10: =if(I$1<>"",iferror(if(if(left(tipp!R9,find(":",tipp!R9)-1)>right(tipp!R9,(len(tipp!R9)-find(":",tipp!R9))),1,if(right(tipp!R9,(len(tipp!R9)-find(":",tipp!R9)))>left(tipp!R9,find(":",tipp!R9)-1),2,"x"))=tipp!$I9,tipp!$J9*pontozas!$B$1)+if(left(tipp!R9,find(":",tipp!R9)-1)-right(tipp!R9,(len(tipp!R9)-find(":",tipp!R9)))=tipp!$G9-tipp!$H9,pontozas!$B$2,0)+if(tipp!R9=tipp!$F9,pontozas!$B$3),""),"") -> 0 | ... O10: =if(O$1<>"",iferror(if(if(left(tipp!X9,find(":",tipp!X9)-1)>right(tipp!X9,(len(tipp!X9)-find(":",tipp!X9))),1,if(right(tipp!X9,(len(tipp!X9)-find(":",tipp!X9)))>left(tipp!X9,find(":",tipp!X9)-1),2,"x"))=tipp!$I9,tipp!$J9*pontozas!$B$1)+if(left(tipp!X9,find(":",tipp!X9)-1)-right(tipp!X9,(len(tipp!X9)-find(":",tipp!X9)))=tipp!$G9-tipp!$H9,pontozas!$B$2,0)+if(tipp!X9=tipp!$F9,pontozas!$B$3),""),"")
A11: =CONCATENATE(tipp!A10&" : "&tipp!B10) -> France : Belarus | B11: =if(B$1<>"",iferror(if(if(left(tipp!K10,find(":",tipp!K10)-1)>right(tipp!K10,(len(tipp!K10)-find(":",tipp!K10))),1,if(right(tipp!K10,(len(tipp!K10)-find(":",tipp!K10)))>left(tipp!K10,find(":",tipp!K10)-1),2,"x"))=tipp!$I10,tipp!$J10*pontozas!$B$1)+if(left(tipp!K10,find(":",tipp!K10)-1)-right(tipp!K10,(len(tipp!K10)-find(":",tipp!K10)))=tipp!$G10-tipp!$H10,pontozas!$B$2,0)+if(tipp!K10=tipp!$F10,pontozas!$B$3),""),"") -> 0 | C11: =if(C$1<>"",iferror(if(if(left(tipp!L10,find(":",tipp!L10)-1)>right(tipp!L10,(len(tipp!L10)-find(":",tipp!L10))),1,if(right(tipp!L10,(len(tipp!L10)-find(":",tipp!L10)))>left(tipp!L10,find(":",tipp!L10)-1),2,"x"))=tipp!$I10,tipp!$J10*pontozas!$B$1)+if(left(tipp!L10,find(":",tipp!L10)-1)-right(tipp!L10,(len(tipp!L10)-find(":",tipp!L10)))=tipp!$G10-tipp!$H10,pontozas!$B$2,0)+if(tipp!L10=tipp!$F10,pontozas!$B$3),""),"") -> 0 | D11: =if(D$1<>"",iferror(if(if(left(tipp!M10,find(":",tipp!M10)-1)>right(tipp!M10,(len(tipp!M10)-find(":",tipp!M10))),1,if(right(tipp!M10,(len(tipp!M10)-find(":",tipp!M10)))>left(tipp!M10,find(":",tipp!M10)-1),2,"x"))=tipp!$I10,tipp!$J10*pontozas!$B$1)+if(left(tipp!M10,find(":",tipp!M10)-1)-right(tipp!M10,(len(tipp!M10)-find(":",tipp!M10)))=tipp!$G10-tipp!$H10,pontozas!$B$2,0)+if(tipp!M10=tipp!$F10,pontozas!$B$3),""),"") -> 2.9 | E11: =if(E$1<>"",iferror(if(if(left(tipp!N10,find(":",tipp!N10)-1)>right(tipp!N10,(len(tipp!N10)-find(":",tipp!N10))),1,if(right(tipp!N10,(len(tipp!N10)-find(":",tipp!N10)))>left(tipp!N10,find(":",tipp!N10)-1),2,"x"))=tipp!$I10,tipp!$J10*pontozas!$B$1)+if(left(tipp!N10,find(":",tipp!N10)-1)-right(tipp!N10,(len(tipp!N10)-find(":",tipp!N10)))=tipp!$G10-tipp!$H10,pontozas!$B$2,0)+if(tipp!N10=tipp!$F10,pontozas!$B$3),""),"") -> 0 | F11: =if(F$1<>"",iferror(if(if(left(tipp!O10,find(":",tipp!O10)-1)>right(tipp!O10,(len(tipp!O10)-find(":",tipp!O10))),1,if(right(tipp!O10,(len(tipp!O10)-find(":",tipp!O10)))>left(tipp!O10,find(":",tipp!O10)-1),2,"x"))=tipp!$I10,tipp!$J10*pontozas!$B$1)+if(left(tipp!O10,find(":",tipp!O10)-1)-right(tipp!O10,(len(tipp!O10)-find(":",tipp!O10)))=tipp!$G10-tipp!$H10,pontozas!$B$2,0)+if(tipp!O10=tipp!$F10,pontozas!$B$3),""),"") -> 0 | G11: =if(G$1<>"",iferror(if(if(left(tipp!P10,find(":",tipp!P10)-1)>right(tipp!P10,(len(tipp!P10)-find(":",tipp!P10))),1,if(right(tipp!P10,(len(tipp!P10)-find(":",tipp!P10)))>left(tipp!P10,find(":",tipp!P10)-1),2,"x"))=tipp!$I10,tipp!$J10*pontozas!$B$1)+if(left(tipp!P10,find(":",tipp!P10)-1)-right(tipp!P10,(len(tipp!P10)-find(":",tipp!P10)))=tipp!$G10-tipp!$H10,pontozas!$B$2,0)+if(tipp!P10=tipp!$F10,pontozas!$B$3),""),"") | H11: =if(H$1<>"",iferror(if(if(left(tipp!Q10,find(":",tipp!Q10)-1)>right(tipp!Q10,(len(tipp!Q10)-find(":",tipp!Q10))),1,if(right(tipp!Q10,(len(tipp!Q10)-find(":",tipp!Q10)))>left(tipp!Q10,find(":",tipp!Q10)-1),2,"x"))=tipp!$I10,tipp!$J10*pontozas!$B$1)+if(left(tipp!Q10,find(":",tipp!Q10)-1)-right(tipp!Q10,(len(tipp!Q10)-find(":",tipp!Q10)))=tipp!$G10-tipp!$H10,pontozas!$B$2,0)+if(tipp!Q10=tipp!$F10,pontozas!$B$3),""),"") -> 2.9 | I11: =if(I$1<>"",iferror(if(if(left(tipp!R10,find(":",tipp!R10)-1)>right(tipp!R10,(len(tipp!R10)-find(":",tipp!R10))),1,if(right(tipp!R10,(len(tipp!R10)-find(":",tipp!R10)))>left(tipp!R10,find(":",tipp!R10)-1),2,"x"))=tipp!$I10,tipp!$J10*pontozas!$B$1)+if(left(tipp!R10,find(":",tipp!R10)-1)-right(tipp!R10,(len(tipp!R10)-find(":",tipp!R10)))=tipp!$G10-tipp!$H10,pontozas!$B$2,0)+if(tipp!R10=tipp!$F10,pontozas!$B$3),""),"") -> 0 | ... O11: =if(O$1<>"",iferror(if(if(left(tipp!X10,find(":",tipp!X10)-1)>right(tipp!X10,(len(tipp!X10)-find(":",tipp!X10))),1,if(right(tipp!X10,(len(tipp!X10)-find(":",tipp!X10)))>left(tipp!X10,find(":",tipp!X10)-1),2,"x"))=tipp!$I10,tipp!$J10*pontozas!$B$1)+if(left(tipp!X10,find(":",tipp!X10)-1)-right(tipp!X10,(len(tipp!X10)-find(":",tipp!X10)))=tipp!$G10-tipp!$H10,pontozas!$B$2,0)+if(tipp!X10=tipp!$F10,pontozas!$B$3),""),"")
A12: =CONCATENATE(tipp!A11&" : "&tipp!B11) -> Czech Republic : Slovakia | B12: =if(B$1<>"",iferror(if(if(left(tipp!K11,find(":",tipp!K11)-1)>right(tipp!K11,(len(tipp!K11)-find(":",tipp!K11))),1,if(right(tipp!K11,(len(tipp!K11)-find(":",tipp!K11)))>left(tipp!K11,find(":",tipp!K11)-1),2,"x"))=tipp!$I11,tipp!$J11*pontozas!$B$1)+if(left(tipp!K11,find(":",tipp!K11)-1)-right(tipp!K11,(len(tipp!K11)-find(":",tipp!K11)))=tipp!$G11-tipp!$H11,pontozas!$B$2,0)+if(tipp!K11=tipp!$F11,pontozas!$B$3),""),"") -> 0 | C12: =if(C$1<>"",iferror(if(if(left(tipp!L11,find(":",tipp!L11)-1)>right(tipp!L11,(len(tipp!L11)-find(":",tipp!L11))),1,if(right(tipp!L11,(len(tipp!L11)-find(":",tipp!L11)))>left(tipp!L11,find(":",tipp!L11)-1),2,"x"))=tipp!$I11,tipp!$J11*pontozas!$B$1)+if(left(tipp!L11,find(":",tipp!L11)-1)-right(tipp!L11,(len(tipp!L11)-find(":",tipp!L11)))=tipp!$G11-tipp!$H11,pontozas!$B$2,0)+if(tipp!L11=tipp!$F11,pontozas!$B$3),""),"") -> 0 | D12: =if(D$1<>"",iferror(if(if(left(tipp!M11,find(":",tipp!M11)-1)>right(tipp!M11,(len(tipp!M11)-find(":",tipp!M11))),1,if(right(tipp!M11,(len(tipp!M11)-find(":",tipp!M11)))>left(tipp!M11,find(":",tipp!M11)-1),2,"x"))=tipp!$I11,tipp!$J11*pontozas!$B$1)+if(left(tipp!M11,find(":",tipp!M11)-1)-right(tipp!M11,(len(tipp!M11)-find(":",tipp!M11)))=tipp!$G11-tipp!$H11,pontozas!$B$2,0)+if(tipp!M11=tipp!$F11,pontozas!$B$3),""),"") -> 0 | E12: =if(E$1<>"",iferror(if(if(left(tipp!N11,find(":",tipp!N11)-1)>right(tipp!N11,(len(tipp!N11)-find(":",tipp!N11))),1,if(right(tipp!N11,(len(tipp!N11)-find(":",tipp!N11)))>left(tipp!N11,find(":",tipp!N11)-1),2,"x"))=tipp!$I11,tipp!$J11*pontozas!$B$1)+if(left(tipp!N11,find(":",tipp!N11)-1)-right(tipp!N11,(len(tipp!N11)-find(":",tipp!N11)))=tipp!$G11-tipp!$H11,pontozas!$B$2,0)+if(tipp!N11=tipp!$F11,pontozas!$B$3),""),"") -> 0 | F12: =if(F$1<>"",iferror(if(if(left(tipp!O11,find(":",tipp!O11)-1)>right(tipp!O11,(len(tipp!O11)-find(":",tipp!O11))),1,if(right(tipp!O11,(len(tipp!O11)-find(":",tipp!O11)))>left(tipp!O11,find(":",tipp!O11)-1),2,"x"))=tipp!$I11,tipp!$J11*pontozas!$B$1)+if(left(tipp!O11,find(":",tipp!O11)-1)-right(tipp!O11,(len(tipp!O11)-find(":",tipp!O11)))=tipp!$G11-tipp!$H11,pontozas!$B$2,0)+if(tipp!O11=tipp!$F11,pontozas!$B$3),""),"") -> 0 | G12: =if(G$1<>"",iferror(if(if(left(tipp!P11,find(":",tipp!P11)-1)>right(tipp!P11,(len(tipp!P11)-find(":",tipp!P11))),1,if(right(tipp!P11,(len(tipp!P11)-find(":",tipp!P11)))>left(tipp!P11,find(":",tipp!P11)-1),2,"x"))=tipp!$I11,tipp!$J11*pontozas!$B$1)+if(left(tipp!P11,find(":",tipp!P11)-1)-right(tipp!P11,(len(tipp!P11)-find(":",tipp!P11)))=tipp!$G11-tipp!$H11,pontozas!$B$2,0)+if(tipp!P11=tipp!$F11,pontozas!$B$3),""),"") | H12: =if(H$1<>"",iferror(if(if(left(tipp!Q11,find(":",tipp!Q11)-1)>right(tipp!Q11,(len(tipp!Q11)-find(":",tipp!Q11))),1,if(right(tipp!Q11,(len(tipp!Q11)-find(":",tipp!Q11)))>left(tipp!Q11,find(":",tipp!Q11)-1),2,"x"))=tipp!$I11,tipp!$J11*pontozas!$B$1)+if(left(tipp!Q11,find(":",tipp!Q11)-1)-right(tipp!Q11,(len(tipp!Q11)-find(":",tipp!Q11)))=tipp!$G11-tipp!$H11,pontozas!$B$2,0)+if(tipp!Q11=tipp!$F11,pontozas!$B$3),""),"") -> 0 | I12: =if(I$1<>"",iferror(if(if(left(tipp!R11,find(":",tipp!R11)-1)>right(tipp!R11,(len(tipp!R11)-find(":",tipp!R11))),1,if(right(tipp!R11,(len(tipp!R11)-find(":",tipp!R11)))>left(tipp!R11,find(":",tipp!R11)-1),2,"x"))=tipp!$I11,tipp!$J11*pontozas!$B$1)+if(left(tipp!R11,find(":",tipp!R11)-1)-right(tipp!R11,(len(tipp!R11)-find(":",tipp!R11)))=tipp!$G11-tipp!$H11,pontozas!$B$2,0)+if(tipp!R11=tipp!$F11,pontozas!$B$3),""),"") -> 7.25 | ... O12: =if(O$1<>"",iferror(if(if(left(tipp!X11,find(":",tipp!X11)-1)>right(tipp!X11,(len(tipp!X11)-find(":",tipp!X11))),1,if(right(tipp!X11,(len(tipp!X11)-find(":",tipp!X11)))>left(tipp!X11,find(":",tipp!X11)-1),2,"x"))=tipp!$I11,tipp!$J11*pontozas!$B$1)+if(left(tipp!X11,find(":",tipp!X11)-1)-right(tipp!X11,(len(tipp!X11)-find(":",tipp!X11)))=tipp!$G11-tipp!$H11,pontozas!$B$2,0)+if(tipp!X11=tipp!$F11,pontozas!$B$3),""),"")
A13: =CONCATENATE(tipp!A12&" : "&tipp!B12) -> Norway : Latvia | B13: =if(B$1<>"",iferror(if(if(left(tipp!K12,find(":",tipp!K12)-1)>right(tipp!K12,(len(tipp!K12)-find(":",tipp!K12))),1,if(right(tipp!K12,(len(tipp!K12)-find(":",tipp!K12)))>left(tipp!K12,find(":",tipp!K12)-1),2,"x"))=tipp!$I12,tipp!$J12*pontozas!$B$1)+if(left(tipp!K12,find(":",tipp!K12)-1)-right(tipp!K12,(len(tipp!K12)-find(":",tipp!K12)))=tipp!$G12-tipp!$H12,pontozas!$B$2,0)+if(tipp!K12=tipp!$F12,pontozas!$B$3),""),"") -> 0 | C13: =if(C$1<>"",iferror(if(if(left(tipp!L12,find(":",tipp!L12)-1)>right(tipp!L12,(len(tipp!L12)-find(":",tipp!L12))),1,if(right(tipp!L12,(len(tipp!L12)-find(":",tipp!L12)))>left(tipp!L12,find(":",tipp!L12)-1),2,"x"))=tipp!$I12,tipp!$J12*pontozas!$B$1)+if(left(tipp!L12,find(":",tipp!L12)-1)-right(tipp!L12,(len(tipp!L12)-find(":",tipp!L12)))=tipp!$G12-tipp!$H12,pontozas!$B$2,0)+if(tipp!L12=tipp!$F12,pontozas!$B$3),""),"") -> 0 | D13: =if(D$1<>"",iferror(if(if(left(tipp!M12,find(":",tipp!M12)-1)>right(tipp!M12,(len(tipp!M12)-find(":",tipp!M12))),1,if(right(tipp!M12,(len(tipp!M12)-find(":",tipp!M12)))>left(tipp!M12,find(":",tipp!M12)-1),2,"x"))=tipp!$I12,tipp!$J12*pontozas!$B$1)+if(left(tipp!M12,find(":",tipp!M12)-1)-right(tipp!M12,(len(tipp!M12)-find(":",tipp!M12)))=tipp!$G12-tipp!$H12,pontozas!$B$2,0)+if(tipp!M12=tipp!$F12,pontozas!$B$3),""),"") -> 0 | E13: =if(E$1<>"",iferror(if(if(left(tipp!N12,find(":",tipp!N12)-1)>right(tipp!N12,(len(tipp!N12)-find(":",tipp!N12))),1,if(right(tipp!N12,(len(tipp!N12)-find(":",tipp!N12)))>left(tipp!N12,find(":",tipp!N12)-1),2,"x"))=tipp!$I12,tipp!$J12*pontozas!$B$1)+if(left(tipp!N12,find(":",tipp!N12)-1)-right(tipp!N12,(len(tipp!N12)-find(":",tipp!N12)))=tipp!$G12-tipp!$H12,pontozas!$B$2,0)+if(tipp!N12=tipp!$F12,pontozas!$B$3),""),"") -> 5 | F13: =if(F$1<>"",iferror(if(if(left(tipp!O12,find(":",tipp!O12)-1)>right(tipp!O12,(len(tipp!O12)-find(":",tipp!O12))),1,if(right(tipp!O12,(len(tipp!O12)-find(":",tipp!O12)))>left(tipp!O12,find(":",tipp!O12)-1),2,"x"))=tipp!$I12,tipp!$J12*pontozas!$B$1)+if(left(tipp!O12,find(":",tipp!O12)-1)-right(tipp!O12,(len(tipp!O12)-find(":",tipp!O12)))=tipp!$G12-tipp!$H12,pontozas!$B$2,0)+if(tipp!O12=tipp!$F12,pontozas!$B$3),""),"") -> 0 | G13: =if(G$1<>"",iferror(if(if(left(tipp!P12,find(":",tipp!P12)-1)>right(tipp!P12,(len(tipp!P12)-find(":",tipp!P12))),1,if(right(tipp!P12,(len(tipp!P12)-find(":",tipp!P12)))>left(tipp!P12,find(":",tipp!P12)-1),2,"x"))=tipp!$I12,tipp!$J12*pontozas!$B$1)+if(left(tipp!P12,find(":",tipp!P12)-1)-right(tipp!P12,(len(tipp!P12)-find(":",tipp!P12)))=tipp!$G12-tipp!$H12,pontozas!$B$2,0)+if(tipp!P12=tipp!$F12,pontozas!$B$3),""),"") | H13: =if(H$1<>"",iferror(if(if(left(tipp!Q12,find(":",tipp!Q12)-1)>right(tipp!Q12,(len(tipp!Q12)-find(":",tipp!Q12))),1,if(right(tipp!Q12,(len(tipp!Q12)-find(":",tipp!Q12)))>left(tipp!Q12,find(":",tipp!Q12)-1),2,"x"))=tipp!$I12,tipp!$J12*pontozas!$B$1)+if(left(tipp!Q12,find(":",tipp!Q12)-1)-right(tipp!Q12,(len(tipp!Q12)-find(":",tipp!Q12)))=tipp!$G12-tipp!$H12,pontozas!$B$2,0)+if(tipp!Q12=tipp!$F12,pontozas!$B$3),""),"") -> 5 | I13: =if(I$1<>"",iferror(if(if(left(tipp!R12,find(":",tipp!R12)-1)>right(tipp!R12,(len(tipp!R12)-find(":",tipp!R12))),1,if(right(tipp!R12,(len(tipp!R12)-find(":",tipp!R12)))>left(tipp!R12,find(":",tipp!R12)-1),2,"x"))=tipp!$I12,tipp!$J12*pontozas!$B$1)+if(left(tipp!R12,find(":",tipp!R12)-1)-right(tipp!R12,(len(tipp!R12)-find(":",tipp!R12)))=tipp!$G12-tipp!$H12,pontozas!$B$2,0)+if(tipp!R12=tipp!$F12,pontozas!$B$3),""),"") -> 6 | ... O13: =if(O$1<>"",iferror(if(if(left(tipp!X12,find(":",tipp!X12)-1)>right(tipp!X12,(len(tipp!X12)-find(":",tipp!X12))),1,if(right(tipp!X12,(len(tipp!X12)-find(":",tipp!X12)))>left(tipp!X12,find(":",tipp!X12)-1),2,"x"))=tipp!$I12,tipp!$J12*pontozas!$B$1)+if(left(tipp!X12,find(":",tipp!X12)-1)-right(tipp!X12,(len(tipp!X12)-find(":",tipp!X12)))=tipp!$G12-tipp!$H12,pontozas!$B$2,0)+if(tipp!X12=tipp!$F12,pontozas!$B$3),""),"")
A14: =CONCATENATE(tipp!A13&" : "&tipp!B13) -> Finland : South Korea | B14: =if(B$1<>"",iferror(if(if(left(tipp!K13,find(":",tipp!K13)-1)>right(tipp!K13,(len(tipp!K13)-find(":",tipp!K13))),1,if(right(tipp!K13,(len(tipp!K13)-find(":",tipp!K13)))>left(tipp!K13,find(":",tipp!K13)-1),2,"x"))=tipp!$I13,tipp!$J13*pontozas!$B$1)+if(left(tipp!K13,find(":",tipp!K13)-1)-right(tipp!K13,(len(tipp!K13)-find(":",tipp!K13)))=tipp!$G13-tipp!$H13,pontozas!$B$2,0)+if(tipp!K13=tipp!$F13,pontozas!$B$3),""),"") -> 1.02 | C14: =if(C$1<>"",iferror(if(if(left(tipp!L13,find(":",tipp!L13)-1)>right(tipp!L13,(len(tipp!L13)-find(":",tipp!L13))),1,if(right(tipp!L13,(len(tipp!L13)-find(":",tipp!L13)))>left(tipp!L13,find(":",tipp!L13)-1),2,"x"))=tipp!$I13,tipp!$J13*pontozas!$B$1)+if(left(tipp!L13,find(":",tipp!L13)-1)-right(tipp!L13,(len(tipp!L13)-find(":",tipp!L13)))=tipp!$G13-tipp!$H13,pontozas!$B$2,0)+if(tipp!L13=tipp!$F13,pontozas!$B$3),""),"") -> 1.02 | D14: =if(D$1<>"",iferror(if(if(left(tipp!M13,find(":",tipp!M13)-1)>right(tipp!M13,(len(tipp!M13)-find(":",tipp!M13))),1,if(right(tipp!M13,(len(tipp!M13)-find(":",tipp!M13)))>left(tipp!M13,find(":",tipp!M13)-1),2,"x"))=tipp!$I13,tipp!$J13*pontozas!$B$1)+if(left(tipp!M13,find(":",tipp!M13)-1)-right(tipp!M13,(len(tipp!M13)-find(":",tipp!M13)))=tipp!$G13-tipp!$H13,pontozas!$B$2,0)+if(tipp!M13=tipp!$F13,pontozas!$B$3),""),"") -> 1.02 | E14: =if(E$1<>"",iferror(if(if(left(tipp!N13,find(":",tipp!N13)-1)>right(tipp!N13,(len(tipp!N13)-find(":",tipp!N13))),1,if(right(tipp!N13,(len(tipp!N13)-find(":",tipp!N13)))>left(tipp!N13,find(":",tipp!N13)-1),2,"x"))=tipp!$I13,tipp!$J13*pontozas!$B$1)+if(left(tipp!N13,find(":",tipp!N13)-1)-right(tipp!N13,(len(tipp!N13)-find(":",tipp!N13)))=tipp!$G13-tipp!$H13,pontozas!$B$2,0)+if(tipp!N13=tipp!$F13,pontozas!$B$3),""),"") -> 1.02 | F14: =if(F$1<>"",iferror(if(if(left(tipp!O13,find(":",tipp!O13)-1)>right(tipp!O13,(len(tipp!O13)-find(":",tipp!O13))),1,if(right(tipp!O13,(len(tipp!O13)-find(":",tipp!O13)))>left(tipp!O13,find(":",tipp!O13)-1),2,"x"))=tipp!$I13,tipp!$J13*pontozas!$B$1)+if(left(tipp!O13,find(":",tipp!O13)-1)-right(tipp!O13,(len(tipp!O13)-find(":",tipp!O13)))=tipp!$G13-tipp!$H13,pontozas!$B$2,0)+if(tipp!O13=tipp!$F13,pontozas!$B$3),""),"") -> 1.02 | G14: =if(G$1<>"",iferror(if(if(left(tipp!P13,find(":",tipp!P13)-1)>right(tipp!P13,(len(tipp!P13)-find(":",tipp!P13))),1,if(right(tipp!P13,(len(tipp!P13)-find(":",tipp!P13)))>left(tipp!P13,find(":",tipp!P13)-1),2,"x"))=tipp!$I13,tipp!$J13*pontozas!$B$1)+if(left(tipp!P13,find(":",tipp!P13)-1)-right(tipp!P13,(len(tipp!P13)-find(":",tipp!P13)))=tipp!$G13-tipp!$H13,pontozas!$B$2,0)+if(tipp!P13=tipp!$F13,pontozas!$B$3),""),"") | H14: =if(H$1<>"",iferror(if(if(left(tipp!Q13,find(":",tipp!Q13)-1)>right(tipp!Q13,(len(tipp!Q13)-find(":",tipp!Q13))),1,if(right(tipp!Q13,(len(tipp!Q13)-find(":",tipp!Q13)))>left(tipp!Q13,find(":",tipp!Q13)-1),2,"x"))=tipp!$I13,tipp!$J13*pontozas!$B$1)+if(left(tipp!Q13,find(":",tipp!Q13)-1)-right(tipp!Q13,(len(tipp!Q13)-find(":",tipp!Q13)))=tipp!$G13-tipp!$H13,pontozas!$B$2,0)+if(tipp!Q13=tipp!$F13,pontozas!$B$3),""),"") -> 2.02 | I14: =if(I$1<>"",iferror(if(if(left(tipp!R13,find(":",tipp!R13)-1)>right(tipp!R13,(len(tipp!R13)-find(":",tipp!R13))),1,if(right(tipp!R13,(len(tipp!R13)-find(":",tipp!R13)))>left(tipp!R13,find(":",tipp!R13)-1),2,"x"))=tipp!$I13,tipp!$J13*pontozas!$B$1)+if(left(tipp!R13,find(":",tipp!R13)-1)-right(tipp!R13,(len(tipp!R13)-find(":",tipp!R13)))=tipp!$G13-tipp!$H13,pontozas!$B$2,0)+if(tipp!R13=tipp!$F13,pontozas!$B$3),""),"") -> 1.02 | ... O14: =if(O$1<>"",iferror(if(if(left(tipp!X13,find(":",tipp!X13)-1)>right(tipp!X13,(len(tipp!X13)-find(":",tipp!X13))),1,if(right(tipp!X13,(len(tipp!X13)-find(":",tipp!X13)))>left(tipp!X13,find(":",tipp!X13)-1),2,"x"))=tipp!$I13,tipp!$J13*pontozas!$B$1)+if(left(tipp!X13,find(":",tipp!X13)-1)-right(tipp!X13,(len(tipp!X13)-find(":",tipp!X13)))=tipp!$G13-tipp!$H13,pontozas!$B$2,0)+if(tipp!X13=tipp!$F13,pontozas!$B$3),""),"")
